Workbook
Name StatusSelesai: Rumus!$B$6
Name StatusJalan: Rumus!$B$7
Name StatusBelum: Rumus!$B$8
Name GsaSudah: Rumus!$B$30
Name GsaSisa: Rumus!$B$31

Sheet Ringkasan
B2: OKTOBER 2026 – JANUARI 2027
B3: Planning Semester 5
B4: Semua angka dan grafik tertaut rumus ke sheet 4 Bulan, WPM, dan GSA (lewat sheet Rumus).
B6: OKTOBER 2026 | E6: NOVEMBER 2026 | H6: DESEMBER 2026 | K6: JANUARI 2027
B7: Berani memulai | E7: Mulai terbiasa | H7: Menjadi terampil | K7: Menerapkan
B9: Public speaking + social openness | E9: Conversation + GSA consistency | H9: Public speaking + technical output | K9: GSA completion + real-world communication
B10: Bangun fondasi tanpa menunggu percaya diri. | E10: Ubah kebiasaan yang baru dimulai menjadi ritme. | H10: Skill mulai menghasilkan karya yang terlihat. | K10: Pakai skill di situasi nyata, finish strong.
B12: =Rumus!B23 | E12: =Rumus!B24 | H12: =Rumus!B25 | K12: =Rumus!B26
B13: =Rumus!E23 | E13: =Rumus!E24 | H13: =Rumus!E25 | K13: =Rumus!E26
B15: Status keseluruhan | F15: Progres per jalur | J15: GSA vs target 36
B31: =Rumus!A6&" "&Rumus!B6 | C31: =Rumus!A7&" "&Rumus!B7 | D31: =Rumus!A8&" "&Rumus!B8 | J31: =Rumus!B30&" / 36 konten"
B33: Lima jalur utama
B34: Communication | D34: Social & Mindset | F34: GSA & Content | H34: Career | J34: Technical
B36: berani → terbiasa → terampil → natural | D36: interaksi → percakapan → relasi | F36: adaptasi → konsistensi → portfolio | H36: eksplorasi → aplikasi → seleksi | J36: Excel → SQL → data analysis
B39: Roadmap
B40: OKTOBER 2026 | E40: NOVEMBER 2026 | H40: DESEMBER 2026 | K40: JANUARI 2027
B41: Berani memulai | E41: Mulai terbiasa | H41: Menjadi terampil | K41: Menerapkan
B43: Apa yang perlu mulai dilakukan tanpa menunggu percaya diri? | E43: Bagaimana membuat perilaku Oktober menjadi lebih natural? | H43: Bagaimana mengubah kebiasaan menjadi kemampuan yang terlihat? | K43: Apakah skill yang dibangun benar-benar bisa dipakai?
B46: Keberanian bicara, tampil, dan membuat konten jadi dasar kenyamanan. | E46: Percakapan, public speaking, GSA, English, dan teknis dilakukan konsisten. | H46: Komunikasi dan teknis mulai menghasilkan output, portfolio, dan kesiapan interview. | K46: Semua kemampuan dipakai di situasi nyata, termasuk finish GSA dan kesiapan karier.
B49: Aturan main
B50: GSA | F50: Kuliah | J50: Mental
B51: 2 konten/minggu. Ranking dan reward adalah bonus. | F51: Prioritas utama. Jangan dikorbankan demi konten. | J51: Progres lebih penting dari kesempurnaan.
B54: Public speaking | F54: WPM | J54: Career
B55: Berani → terbiasa → terampil. Anxiety tidak harus 0. | F55: +10 WPM per bulan. Akurasi tetap penting (≥95%). | J55: Eksplorasi → aplikasi → seleksi. Bangun CV + portfolio.

Sheet 4 Bulan
A2: 4 BLOK BULAN · sumber data achievement
A3: Isi kolom Progress (0–100) atau biarkan rumus otomatis (WPM/GSA). Status terhitung dari Progress. Ringkasan, pie, dan sheet lain membaca sheet ini.
A5: OKTOBER 2026 · BERANI MEMULAI · Public speaking + social openness
A6: Bulan | B6: Jalur | C6: Pencapaian | D6: Target akhir bulan | E6: Indikator | F6: Prioritas | G6: Status | H6: Progress | I6: Catatan | J6: Sumber rumus
A7: Okt | B7: Communication | C7: Public speaking — berani bicara | D7: Berani menyampaikan pendapat dan berbicara 1–3 menit meskipun masih gugup | E7: Tidak menghindari kesempatan bicara; minimal 1 sesi latihan/minggu | F7: Utama | G7: =IF(H7>=100,"Selesai",IF(H7>0,"Jalan","Belum")) | H7: 0 | J7: input manual
A8: Okt | B8: Social & Mindset | C8: Banyakin senyum & ekspresi ramah | D8: Lebih sering menunjukkan ekspresi ramah saat bertemu/berbicara | E8: Lebih sering tersenyum dan membuka interaksi | F8: Sedang | G8: =IF(H8>=100,"Selesai",IF(H8>0,"Jalan","Belum")) | H8: 0 | J8: input manual
A9: Okt | B9: Social & Mindset | C9: Lebih terbuka dengan orang lain | D9: Mulai sengaja membuka percakapan beberapa kali dalam seminggu | E9: Ada inisiatif menyapa/bertanya tanpa selalu menunggu | F9: Utama | G9: =IF(H9>=100,"Selesai",IF(H9>0,"Jalan","Belum")) | H9: 0 | J9: input manual
A10: Okt | B10: Social & Mindset | C10: Kurangi self-judgment | D10: Menyadari saat mulai menghakimi diri dan menggantinya dengan evaluasi | E10: Menulis apa yang terjadi dan apa yang bisa diperbaiki, tanpa label negatif | F10: Utama | G10: =IF(H10>=100,"Selesai",IF(H10>0,"Jalan","Belum")) | H10: 0 | J10: input manual
A11: Okt | B11: GSA & Content | C11: Adaptasi GSA | D11: Memahami ritme GSA dan mengikuti kegiatan yang diperlukan | E11: Meeting/briefing penting diikuti; alur kerja dipahami | F11: Utama | G11: =IF(H11>=100,"Selesai",IF(H11>0,"Jalan","Belum")) | H11: 0 | J11: input manual
A12: Okt | B12: GSA & Content | C12: Konsisten membuat konten | D12: 2 konten per minggu tanpa mengorbankan kuliah dan kesehatan | E12: Jumlah konten mingguan tercapai secara realistis | F12: Utama | G12: =IF(H12>=100,"Selesai",IF(H12>0,"Jalan","Belum")) | H12: =IFERROR(MIN(100,SUM(GSA!D6:D10)/10*100),0) | J12: GSA!D6:D10 / 10
A13: Okt | B13: English | C13: Fondasi bahasa Inggris | D13: Menyelesaikan bagian awal buku dan mulai speaking/listening | E13: Mampu melakukan percakapan sederhana | F13: Sedang | G13: =IF(H13>=100,"Selesai",IF(H13>0,"Jalan","Belum")) | H13: 0 | J13: input manual
A14: Okt | B14: Technical | C14: Excel & statistik dasar | D14: Memahami dasar Excel dan statistik untuk analisis data | E14: Bisa memakai formula dasar, filter/sort, dan statistik dasar | F14: Utama | G14: =IF(H14>=100,"Selesai",IF(H14>0,"Jalan","Belum")) | H14: 0 | J14: input manual
A15: Okt | B15: Technical | C15: Typing 60 WPM | D15: 60 WPM dengan akurasi baik | E15: Mencapai 60 WPM secara konsisten | F15: Sedang | G15: =IF(H15>=100,"Selesai",IF(H15>0,"Jalan","Belum")) | H15: =IFERROR(MIN(100,N(WPM!D6)/60*100),0) | J15: WPM!D6 / 60
A16: Okt | B16: Career | C16: Eksplorasi magang | D16: Menentukan bidang dan daftar target magang; siapkan CV/dokumen | E16: Daftar target + CV awal siap | F16: Utama | G16: =IF(H16>=100,"Selesai",IF(H16>0,"Jalan","Belum")) | H16: 0 | J16: input manual
A17: Okt | B17: Academic | C17: Sistem kuliah | D17: Catatan lebih rapi dan materi penting tersimpan di Google Drive | E17: Catatan mingguan dan file materi terdokumentasi | F17: Utama | G17: =IF(H17>=100,"Selesai",IF(H17>0,"Jalan","Belum")) | H17: 0 | J17: input manual
A18: Ringkasan Oktober 2026 | G18: =COUNTIF(G7:G17,"Selesai")&" selesai / "&COUNTA(A7:A17) | H18: =IFERROR(AVERAGE(H7:H17)/100,0) | J18: G7:H17
A20: NOVEMBER 2026 · MULAI TERBIASA · Conversation + GSA consistency
A21: Bulan | B21: Jalur | C21: Pencapaian | D21: Target akhir bulan | E21: Indikator | F21: Prioritas | G21: Status | H21: Progress | I21: Catatan | J21: Sumber rumus
A22: Nov | B22: Communication | C22: Public speaking — nyaman | D22: Presentasi 3–5 menit dan mulai improvisasi tanpa teks penuh | E22: Bisa berbicara dengan struktur sederhana dan tidak cepat blank | F22: Utama | G22: =IF(H22>=100,"Selesai",IF(H22>0,"Jalan","Belum")) | H22: 0 | J22: input manual
A23: Nov | B23: Social & Mindset | C23: Mempertahankan percakapan | D23: Mampu melanjutkan percakapan dan lebih aktif bertanya | E23: Tidak cepat mengakhiri interaksi karena overthinking | F23: Utama | G23: =IF(H23>=100,"Selesai",IF(H23>0,"Jalan","Belum")) | H23: 0 | J23: input manual
A24: Nov | B24: Social & Mindset | C24: Self-judgment → evaluasi | D24: Membedakan 'aku melakukan kesalahan' dari 'aku gagal' | E24: Kesalahan sosial dinilai sebagai data untuk perbaikan | F24: Utama | G24: =IF(H24>=100,"Selesai",IF(H24>0,"Jalan","Belum")) | H24: 0 | J24: input manual
A25: Nov | B25: GSA & Content | C25: Konsistensi & gaya konten | D25: 2 konten per minggu dan mulai menemukan gaya komunikasi | E25: Punya bank ide dan beberapa format yang konsisten | F25: Utama | G25: =IF(H25>=100,"Selesai",IF(H25>0,"Jalan","Belum")) | H25: =IFERROR(MIN(100,SUM(GSA!D11:D14)/8*100),0) | J25: GSA!D11:D14 / 8
A26: Nov | B26: English | C26: Percakapan sehari-hari | D26: Lebih lancar dalam speaking/listening | E26: Tidak terlalu sering menerjemahkan setiap kalimat di kepala | F26: Sedang | G26: =IF(H26>=100,"Selesai",IF(H26>0,"Jalan","Belum")) | H26: 0 | J26: input manual
A27: Nov | B27: Technical | C27: Excel menengah + SQL dasar | D27: PivotTable, formula penting, visualisasi; SQL SELECT/WHERE/GROUP BY/JOIN | E27: Bisa mengerjakan kasus data sederhana | F27: Utama | G27: =IF(H27>=100,"Selesai",IF(H27>0,"Jalan","Belum")) | H27: 0 | J27: input manual
A28: Nov | B28: Technical | C28: Typing 70 WPM | D28: 70 WPM dengan akurasi baik | E28: Mencapai 70 WPM secara konsisten | F28: Sedang | G28: =IF(H28>=100,"Selesai",IF(H28>0,"Jalan","Belum")) | H28: =IFERROR(MIN(100,N(WPM!D7)/70*100),0) | J28: WPM!D7 / 70
A29: Nov | B29: Career | C29: Mulai mendaftar magang | D29: CV final dan beberapa lamaran terkirim | E29: Ada bukti aplikasi yang dikirim | F29: Utama | G29: =IF(H29>=100,"Selesai",IF(H29>0,"Jalan","Belum")) | H29: 0 | J29: input manual
A30: Nov | B30: Technical | C30: Digital product | D30: Menyelesaikan 1 digital product sederhana | E30: Ada versi yang dapat ditunjukkan/didemokan | F30: Sedang | G30: =IF(H30>=100,"Selesai",IF(H30>0,"Jalan","Belum")) | H30: 0 | J30: input manual
A31: Ringkasan November 2026 | G31: =COUNTIF(G22:G30,"Selesai")&" selesai / "&COUNTA(A22:A30) | H31: =IFERROR(AVERAGE(H22:H30)/100,0) | J31: G22:H30
A33: DESEMBER 2026 · MENJADI TERAMPIL · Public speaking + technical output
A34: Bulan | B34: Jalur | C34: Pencapaian | D34: Target akhir bulan | E34: Indikator | F34: Prioritas | G34: Status | H34: Progress | I34: Catatan | J34: Sumber rumus
A35: Des | B35: Communication | C35: Public speaking — terampil | D35: Presentasi 5–10 menit, runtut, minim ketergantungan pada teks | E35: Bisa menjelaskan dan merespons pertanyaan lebih stabil | F35: Utama | G35: =IF(H35>=100,"Selesai",IF(H35>0,"Jalan","Belum")) | H35: 0 | J35: input manual
A36: Des | B36: Social & Mindset | C36: Lebih natural dalam kelompok | D36: Aktif berdiskusi dan lebih nyaman berbicara dengan orang baru | E36: Mulai berinisiatif ikut percakapan/kelompok | F36: Utama | G36: =IF(H36>=100,"Selesai",IF(H36>0,"Jalan","Belum")) | H36: 0 | J36: input manual
A37: Des | B37: Social & Mindset | C37: Mengurangi takut dinilai | D37: Tidak terlalu lama memikirkan interaksi yang tidak sempurna | E37: Lebih cepat kembali ke aktivitas setelah interaksi | F37: Utama | G37: =IF(H37>=100,"Selesai",IF(H37>0,"Jalan","Belum")) | H37: 0 | J37: input manual
A38: Des | B38: GSA & Content | C38: Pengembangan personal branding | D38: 2 konten per minggu dan gaya konten lebih jelas | E38: Storytelling/editing/penyampaian makin konsisten | F38: Utama | G38: =IF(H38>=100,"Selesai",IF(H38>0,"Jalan","Belum")) | H38: =IFERROR(MIN(100,SUM(GSA!D15:D18)/8*100),0) | J38: GSA!D15:D18 / 8
A39: Des | B39: English | C39: Fluency bertahap | D39: Mampu berbicara lebih panjang dan menjelaskan opini sederhana | E39: Lebih nyaman tanpa terjemahan terus-menerus | F39: Sedang | G39: =IF(H39>=100,"Selesai",IF(H39>0,"Jalan","Belum")) | H39: 0 | J39: input manual
A40: Des | B40: Technical | C40: Excel + data analysis | D40: Memakai Excel untuk analisis data sederhana dan statistik dasar | E40: Ada minimal 1 hasil analisis yang rapi | F40: Utama | G40: =IF(H40>=100,"Selesai",IF(H40>0,"Jalan","Belum")) | H40: 0 | J40: input manual
A41: Des | B41: Technical | C41: Typing 80 WPM | D41: 80 WPM dengan akurasi baik | E41: Mencapai 80 WPM secara konsisten | F41: Sedang | G41: =IF(H41>=100,"Selesai",IF(H41>0,"Jalan","Belum")) | H41: =IFERROR(MIN(100,N(WPM!D8)/80*100),0) | J41: WPM!D8 / 80
A42: Des | B42: Career | C42: Persiapan interview | D42: CV + portfolio siap; latihan pertanyaan interview | E42: Mampu menjawab pertanyaan umum lebih terstruktur | F42: Utama | G42: =IF(H42>=100,"Selesai",IF(H42>0,"Jalan","Belum")) | H42: 0 | J42: input manual
A43: Des | B43: Academic | C43: Arah skripsi | D43: Memiliki 1–3 kandidat topik yang realistis | E43: Ada alasan dan arah awal untuk tiap kandidat | F43: Sedang | G43: =IF(H43>=100,"Selesai",IF(H43>0,"Jalan","Belum")) | H43: 0 | J43: input manual
A44: Ringkasan Desember 2026 | G44: =COUNTIF(G35:G43,"Selesai")&" selesai / "&COUNTA(A35:A43) | H44: =IFERROR(AVERAGE(H35:H43)/100,0) | J44: G35:H43
...

Sheet WPM
A2: WPM · tertaut ke Typing di sheet 4 Bulan
A3: Isi Aktual WPM. Progress baris Typing (60/70/80/90) di 4 Bulan ikut terhitung. Status memakai target + akurasi.
A5: Bulan | B5: Fase | C5: Target WPM | D5: Aktual WPM | E5: Gap | F5: Akurasi target | G5: Aktual akurasi | H5: Status
A6: Oktober 2026 | B6: Berani memulai | C6: 60 | D6: 0 | E6: =IF(D6="",C6,C6-D6) | F6: 0.95 | H6: =IF(OR(D6="",D6=0),"Belum",IF(AND(D6>=C6,OR(G6="",G6>=F6)),"Tercapai","Jalan"))
A7: November 2026 | B7: Mulai terbiasa | C7: 70 | D7: 0 | E7: =IF(D7="",C7,C7-D7) | F7: 0.95 | H7: =IF(OR(D7="",D7=0),"Belum",IF(AND(D7>=C7,OR(G7="",G7>=F7)),"Tercapai","Jalan"))
A8: Desember 2026 | B8: Menjadi terampil | C8: 80 | D8: 0 | E8: =IF(D8="",C8,C8-D8) | F8: 0.95 | H8: =IF(OR(D8="",D8=0),"Belum",IF(AND(D8>=C8,OR(G8="",G8>=F8)),"Tercapai","Jalan"))
A9: Januari 2027 | B9: Menerapkan | C9: 90 | D9: 0 | E9: =IF(D9="",C9,C9-D9) | F9: 0.95 | H9: =IF(OR(D9="",D9=0),"Belum",IF(AND(D9>=C9,OR(G9="",G9>=F9)),"Tercapai","Jalan"))

Sheet GSA
A2: GSA · tertaut ke doughnut Ringkasan & baris konten 4 Bulan
A3: Isi Aktual tiap minggu. Total, pie, dan progress 'konsisten membuat konten' mengikuti rumus SUM.
A5: Minggu | B5: Periode | C5: Target | D5: Aktual | E5: Gap | F5: Status | G5: Ide / topik | H5: Catatan
A6: 1 | B6: 1–7 Okt | C6: 2 | D6: 0 | E6: =C6-D6 | F6: =IF(D6>=C6,"Tercapai",IF(D6>0,"Jalan","Belum"))
A7: 2 | B7: 8–14 Okt | C7: 2 | D7: 0 | E7: =C7-D7 | F7: =IF(D7>=C7,"Tercapai",IF(D7>0,"Jalan","Belum"))
A8: 3 | B8: 15–21 Okt | C8: 2 | D8: 0 | E8: =C8-D8 | F8: =IF(D8>=C8,"Tercapai",IF(D8>0,"Jalan","Belum"))
A9: 4 | B9: 22–28 Okt | C9: 2 | D9: 0 | E9: =C9-D9 | F9: =IF(D9>=C9,"Tercapai",IF(D9>0,"Jalan","Belum"))
A10: 5 | B10: 29 Okt – 4 Nov | C10: 2 | D10: 0 | E10: =C10-D10 | F10: =IF(D10>=C10,"Tercapai",IF(D10>0,"Jalan","Belum"))
A11: 6 | B11: 5–11 Nov | C11: 2 | D11: 0 | E11: =C11-D11 | F11: =IF(D11>=C11,"Tercapai",IF(D11>0,"Jalan","Belum"))
A12: 7 | B12: 12–18 Nov | C12: 2 | D12: 0 | E12: =C12-D12 | F12: =IF(D12>=C12,"Tercapai",IF(D12>0,"Jalan","Belum"))
A13: 8 | B13: 19–25 Nov | C13: 2 | D13: 0 | E13: =C13-D13 | F13: =IF(D13>=C13,"Tercapai",IF(D13>0,"Jalan","Belum"))
A14: 9 | B14: 26 Nov – 2 Des | C14: 2 | D14: 0 | E14: =C14-D14 | F14: =IF(D14>=C14,"Tercapai",IF(D14>0,"Jalan","Belum"))
A15: 10 | B15: 3–9 Des | C15: 2 | D15: 0 | E15: =C15-D15 | F15: =IF(D15>=C15,"Tercapai",IF(D15>0,"Jalan","Belum"))
A16: 11 | B16: 10–16 Des | C16: 2 | D16: 0 | E16: =C16-D16 | F16: =IF(D16>=C16,"Tercapai",IF(D16>0,"Jalan","Belum"))
A17: 12 | B17: 17–23 Des | C17: 2 | D17: 0 | E17: =C17-D17 | F17: =IF(D17>=C17,"Tercapai",IF(D17>0,"Jalan","Belum"))
... A23: 18 | B23: 28–31 Jan | C23: 2 | D23: 0 | E23: =C23-D23 | F23: =IF(D23>=C23,"Tercapai",IF(D23>0,"Jalan","Belum"))
A25: Total aktual (rumus) | D25: =SUM(D6:D23)
A26: Target semester | D26: 36
A27: Progress GSA | D27: =IFERROR(D25/D26,0)

Sheet Rumus
A1: MESIN RUMUS · semua visual membaca sel di sini
A2: Jangan hapus sheet ini. Ubah data hanya di 4 Bulan / WPM / GSA — angka di bawah mengikuti otomatis.
A4: STATUS KESELURUHAN
A5: Label | B5: Jumlah
A6: Selesai | B6: =COUNTIF('4 Bulan'!G:G,"Selesai")
A7: Jalan | B7: =COUNTIF('4 Bulan'!G:G,"Jalan")
A8: Belum | B8: =COUNTIF('4 Bulan'!G:G,"Belum")
A9: Kode | B9: COUNTIF('4 Bulan'!G:G)
A11: JALUR (pie)
A12: Jalur | B12: Rata progress | C12: Jumlah item | D12: Nilai pie | E12: Kode
A13: Komunikasi | B13: =IFERROR(AVERAGEIF('4 Bulan'!B:B,"Communication",'4 Bulan'!H:H),0) | C13: =COUNTIF('4 Bulan'!B:B,"Communication") | D13: =IF(SUM($B$13:$B$19)=0,C13,B13) | E13: jika semua 0 → jumlah item; jika ada progres → rata progress
A14: Sosial | B14: =IFERROR(AVERAGEIF('4 Bulan'!B:B,"Social & Mindset",'4 Bulan'!H:H),0) | C14: =COUNTIF('4 Bulan'!B:B,"Social & Mindset") | D14: =IF(SUM($B$13:$B$19)=0,C14,B14) | E14: jika semua 0 → jumlah item; jika ada progres → rata progress
A15: GSA | B15: =IFERROR(AVERAGEIF('4 Bulan'!B:B,"GSA & Content",'4 Bulan'!H:H),0) | C15: =COUNTIF('4 Bulan'!B:B,"GSA & Content") | D15: =IF(SUM($B$13:$B$19)=0,C15,B15) | E15: jika semua 0 → jumlah item; jika ada progres → rata progress
A16: English | B16: =IFERROR(AVERAGEIF('4 Bulan'!B:B,"English",'4 Bulan'!H:H),0) | C16: =COUNTIF('4 Bulan'!B:B,"English") | D16: =IF(SUM($B$13:$B$19)=0,C16,B16) | E16: jika semua 0 → jumlah item; jika ada progres → rata progress
A17: Teknis | B17: =IFERROR(AVERAGEIF('4 Bulan'!B:B,"Technical",'4 Bulan'!H:H),0) | C17: =COUNTIF('4 Bulan'!B:B,"Technical") | D17: =IF(SUM($B$13:$B$19)=0,C17,B17) | E17: jika semua 0 → jumlah item; jika ada progres → rata progress
A18: Karier | B18: =IFERROR(AVERAGEIF('4 Bulan'!B:B,"Career",'4 Bulan'!H:H),0) | C18: =COUNTIF('4 Bulan'!B:B,"Career") | D18: =IF(SUM($B$13:$B$19)=0,C18,B18) | E18: jika semua 0 → jumlah item; jika ada progres → rata progress
A19: Kuliah | B19: =IFERROR(AVERAGEIF('4 Bulan'!B:B,"Academic",'4 Bulan'!H:H),0) | C19: =COUNTIF('4 Bulan'!B:B,"Academic") | D19: =IF(SUM($B$13:$B$19)=0,C19,B19) | E19: jika semua 0 → jumlah item; jika ada progres → rata progress
A21: 4 BULAN (kartu dashboard)
A22: Kode | B22: Rata % | C22: Selesai | D22: Total | E22: Label kartu | F22: Kode
A23: Okt | B23: =IFERROR(AVERAGE('4 Bulan'!H7:H17)/100,0) | C23: =COUNTIF('4 Bulan'!G7:G17,"Selesai") | D23: =COUNTA('4 Bulan'!A7:A17) | E23: =C23&" / "&D23&" selesai" | F23: AVERAGE/COUNTIF 4 Bulan!H7:H17
A24: Nov | B24: =IFERROR(AVERAGE('4 Bulan'!H22:H30)/100,0) | C24: =COUNTIF('4 Bulan'!G22:G30,"Selesai") | D24: =COUNTA('4 Bulan'!A22:A30) | E24: =C24&" / "&D24&" selesai" | F24: AVERAGE/COUNTIF 4 Bulan!H22:H30
A25: Des | B25: =IFERROR(AVERAGE('4 Bulan'!H35:H43)/100,0) | C25: =COUNTIF('4 Bulan'!G35:G43,"Selesai") | D25: =COUNTA('4 Bulan'!A35:A43) | E25: =C25&" / "&D25&" selesai" | F25: AVERAGE/COUNTIF 4 Bulan!H35:H43
A26: Jan | B26: =IFERROR(AVERAGE('4 Bulan'!H48:H53)/100,0) | C26: =COUNTIF('4 Bulan'!G48:G53,"Selesai") | D26: =COUNTA('4 Bulan'!A48:A53) | E26: =C26&" / "&D26&" selesai" | F26: AVERAGE/COUNTIF 4 Bulan!H48:H53
A28: GSA
A29: Label | B29: Nilai
A30: Sudah | B30: =SUM(GSA!D6:D23)
A31: Sisa target | B31: =MAX(0,36-B30)
A32: Progress | B32: =IFERROR(B30/36,0)
A33: Kode | B33: SUM(GSA!D6:D23) dan 36-konten
A35: WPM (live ke grafik)
A36: Bulan | B36: Target | C36: Aktual
A37: Okt | B37: =WPM!C6 | C37: =N(WPM!D6)
A38: Nov | B38: =WPM!C7 | C38: =N(WPM!D7)
A39: Des | B39: =WPM!C8 | C39: =N(WPM!D8)
A40: Jan | B40: =WPM!C9 | C40: =N(WPM!D9)

Sheet Cara pakai
B2: Cara kerja tautan antar-sheet
B4: 1. Isi data di 4 Bulan (Progress 0–100), WPM (Aktual WPM), dan GSA (Aktual konten). Jangan ketik di kolom Status — itu rumus.
B5: 2. Status di 4 Bulan = IF(Progress>=100,"Selesai",IF(Progress>0,"Jalan","Belum")).
B6: 3. Baris Typing 60/70/80/90 mengambil WPM!D6:D9: Progress = MIN(100, aktual/target*100).
B7: 4. Baris konsistensi konten per bulan = SUM aktual GSA minggu bulan itu / target konten bulan itu.
B8: 5. Sheet Rumus menghitung COUNTIF/AVERAGEIF/SUM dari ketiga sheet sumber. Pie dan kartu Ringkasan merujuk sel Rumus.
B9: 6. Ganti angka di 4 Bulan / WPM / GSA → tekan Enter → Ringkasan, pie, dan kartu bulan berubah (Excel: enable automatic calculation).
B10: 7. Buka di Microsoft Excel. Google Sheets mendukung rumusnya; chart Excel kadang perlu dibuat ulang di Sheets.
B11: 8. Sheet Rumus adalah mesin kode. Jangan hapus. Named ranges: StatusSelesai, StatusJalan, StatusBelum, GsaSudah, GsaSisa.
